Workbook

Sheet Notes
A1: T53 / T54 preset matrices (channel II) — transcription, p.35 and p.37 circuits
A2: Bus drive voltage (V) | B2: 10
A3: Pull-down resistor (kΩ) | B3: 10
A5: Level model as in the T51/T52 sheets (inference): 10 V × 10k/(R+10k); J = diode only.
A6: T53 = channel II buses A–F (BA II1–II6). T54 = channel II buses A–E (BA II7–II11); bus F unused. Bus-to-button order unverified.
A7: The T53 wiring page (p.36) is a copy of the T51 wiring page under a T53 title (same printed values), so it gives no independent T53 revision data. T54 wiring page not supplied.
A8: Both circuit diagrams already show the later values: drawn T53 ≈ T51 revised (p.32 new values), drawn T54 ≈ T52 revised (p.34 new values). See Compare sheet.
A9: Low confidence: T53 B14 (7.5K vs 75K), T53 F22 (12K), T54 C15 (3.9K vs 3.7K), T54 C22 (6.7K/12K triangle, new 12K assumed), T54 C25 (26K or 36K), rows 25–26 triangle-marked special diodes.

Sheet T53 p35
A1: T53 as drawn (p.35)
A2: Row | B2: Slider / function | C2: Bus A (R, kΩ) | D2: Bus B (R, kΩ) | E2: Bus C (R, kΩ) | F2: Bus D (R, kΩ) | G2: Bus E (R, kΩ) | H2: Bus F (R, kΩ) | J2: A level (V) | K2: B level (V) | L2: C level (V) | M2: D level (V) | N2: E level (V) | O2: F level (V)
A3: 1 | B3: VR1 Speed | J3: =IF(C3="","",IF(C3="J",Notes!$B$2,Notes!$B$2*Notes!$B$3/(C3+Notes!$B$3))) | K3: =IF(D3="","",IF(D3="J",Notes!$B$2,Notes!$B$2*Notes!$B$3/(D3+Notes!$B$3))) | L3: =IF(E3="","",IF(E3="J",Notes!$B$2,Notes!$B$2*Notes!$B$3/(E3+Notes!$B$3))) | M3: =IF(F3="","",IF(F3="J",Notes!$B$2,Notes!$B$2*Notes!$B$3/(F3+Notes!$B$3))) | N3: =IF(G3="","",IF(G3="J",Notes!$B$2,Notes!$B$2*Notes!$B$3/(G3+Notes!$B$3))) | O3: =IF(H3="","",IF(H3="J",Notes!$B$2,Notes!$B$2*Notes!$B$3/(H3+Notes!$B$3)))
A4: 2 | B4: VR2 PWM | H4: 110 | J4: =IF(C4="","",IF(C4="J",Notes!$B$2,Notes!$B$2*Notes!$B$3/(C4+Notes!$B$3))) | K4: =IF(D4="","",IF(D4="J",Notes!$B$2,Notes!$B$2*Notes!$B$3/(D4+Notes!$B$3))) | L4: =IF(E4="","",IF(E4="J",Notes!$B$2,Notes!$B$2*Notes!$B$3/(E4+Notes!$B$3))) | M4: =IF(F4="","",IF(F4="J",Notes!$B$2,Notes!$B$2*Notes!$B$3/(F4+Notes!$B$3))) | N4: =IF(G4="","",IF(G4="J",Notes!$B$2,Notes!$B$2*Notes!$B$3/(G4+Notes!$B$3))) | O4: =IF(H4="","",IF(H4="J",Notes!$B$2,Notes!$B$2*Notes!$B$3/(H4+Notes!$B$3)))
A5: 3 | B5: VR3 PW | G5: 7.5 | H5: J | J5: =IF(C5="","",IF(C5="J",Notes!$B$2,Notes!$B$2*Notes!$B$3/(C5+Notes!$B$3))) | K5: =IF(D5="","",IF(D5="J",Notes!$B$2,Notes!$B$2*Notes!$B$3/(D5+Notes!$B$3))) | L5: =IF(E5="","",IF(E5="J",Notes!$B$2,Notes!$B$2*Notes!$B$3/(E5+Notes!$B$3))) | M5: =IF(F5="","",IF(F5="J",Notes!$B$2,Notes!$B$2*Notes!$B$3/(F5+Notes!$B$3))) | N5: =IF(G5="","",IF(G5="J",Notes!$B$2,Notes!$B$2*Notes!$B$3/(G5+Notes!$B$3))) | O5: =IF(H5="","",IF(H5="J",Notes!$B$2,Notes!$B$2*Notes!$B$3/(H5+Notes!$B$3)))
A6: 4 | B6: SW1 square | G6: J | H6: J | J6: =IF(C6="","",IF(C6="J",Notes!$B$2,Notes!$B$2*Notes!$B$3/(C6+Notes!$B$3))) | K6: =IF(D6="","",IF(D6="J",Notes!$B$2,Notes!$B$2*Notes!$B$3/(D6+Notes!$B$3))) | L6: =IF(E6="","",IF(E6="J",Notes!$B$2,Notes!$B$2*Notes!$B$3/(E6+Notes!$B$3))) | M6: =IF(F6="","",IF(F6="J",Notes!$B$2,Notes!$B$2*Notes!$B$3/(F6+Notes!$B$3))) | N6: =IF(G6="","",IF(G6="J",Notes!$B$2,Notes!$B$2*Notes!$B$3/(G6+Notes!$B$3))) | O6: =IF(H6="","",IF(H6="J",Notes!$B$2,Notes!$B$2*Notes!$B$3/(H6+Notes!$B$3)))
A7: 5 | B7: SW2 saw/ramp | C7: J | D7: J | E7: J | F7: J | H7: J | J7: =IF(C7="","",IF(C7="J",Notes!$B$2,Notes!$B$2*Notes!$B$3/(C7+Notes!$B$3))) | K7: =IF(D7="","",IF(D7="J",Notes!$B$2,Notes!$B$2*Notes!$B$3/(D7+Notes!$B$3))) | L7: =IF(E7="","",IF(E7="J",Notes!$B$2,Notes!$B$2*Notes!$B$3/(E7+Notes!$B$3))) | M7: =IF(F7="","",IF(F7="J",Notes!$B$2,Notes!$B$2*Notes!$B$3/(F7+Notes!$B$3))) | N7: =IF(G7="","",IF(G7="J",Notes!$B$2,Notes!$B$2*Notes!$B$3/(G7+Notes!$B$3))) | O7: =IF(H7="","",IF(H7="J",Notes!$B$2,Notes!$B$2*Notes!$B$3/(H7+Notes!$B$3)))
A8: 6 | B8: VR4 Noise | J8: =IF(C8="","",IF(C8="J",Notes!$B$2,Notes!$B$2*Notes!$B$3/(C8+Notes!$B$3))) | K8: =IF(D8="","",IF(D8="J",Notes!$B$2,Notes!$B$2*Notes!$B$3/(D8+Notes!$B$3))) | L8: =IF(E8="","",IF(E8="J",Notes!$B$2,Notes!$B$2*Notes!$B$3/(E8+Notes!$B$3))) | M8: =IF(F8="","",IF(F8="J",Notes!$B$2,Notes!$B$2*Notes!$B$3/(F8+Notes!$B$3))) | N8: =IF(G8="","",IF(G8="J",Notes!$B$2,Notes!$B$2*Notes!$B$3/(G8+Notes!$B$3))) | O8: =IF(H8="","",IF(H8="J",Notes!$B$2,Notes!$B$2*Notes!$B$3/(H8+Notes!$B$3)))
A9: 7 | B9: HPF (BA fo1/fo3) | C9: 6.2 | D9: 27 | F9: 27 | J9: =IF(C9="","",IF(C9="J",Notes!$B$2,Notes!$B$2*Notes!$B$3/(C9+Notes!$B$3))) | K9: =IF(D9="","",IF(D9="J",Notes!$B$2,Notes!$B$2*Notes!$B$3/(D9+Notes!$B$3))) | L9: =IF(E9="","",IF(E9="J",Notes!$B$2,Notes!$B$2*Notes!$B$3/(E9+Notes!$B$3))) | M9: =IF(F9="","",IF(F9="J",Notes!$B$2,Notes!$B$2*Notes!$B$3/(F9+Notes!$B$3))) | N9: =IF(G9="","",IF(G9="J",Notes!$B$2,Notes!$B$2*Notes!$B$3/(G9+Notes!$B$3))) | O9: =IF(H9="","",IF(H9="J",Notes!$B$2,Notes!$B$2*Notes!$B$3/(H9+Notes!$B$3)))
A10: 8 | B10: VR6 RESH | C10: J | D10: J | E10: J | F10: 15 | G10: J | H10: J | J10: =IF(C10="","",IF(C10="J",Notes!$B$2,Notes!$B$2*Notes!$B$3/(C10+Notes!$B$3))) | K10: =IF(D10="","",IF(D10="J",Notes!$B$2,Notes!$B$2*Notes!$B$3/(D10+Notes!$B$3))) | L10: =IF(E10="","",IF(E10="J",Notes!$B$2,Notes!$B$2*Notes!$B$3/(E10+Notes!$B$3))) | M10: =IF(F10="","",IF(F10="J",Notes!$B$2,Notes!$B$2*Notes!$B$3/(F10+Notes!$B$3))) | N10: =IF(G10="","",IF(G10="J",Notes!$B$2,Notes!$B$2*Notes!$B$3/(G10+Notes!$B$3))) | O10: =IF(H10="","",IF(H10="J",Notes!$B$2,Notes!$B$2*Notes!$B$3/(H10+Notes!$B$3)))
A11: 9 | B11: LPF (BA fo2/fo4) | C11: 0.75 | D11: 1.6 | E11: 4.3 | F11: 13 | G11: 12 | J11: =IF(C11="","",IF(C11="J",Notes!$B$2,Notes!$B$2*Notes!$B$3/(C11+Notes!$B$3))) | K11: =IF(D11="","",IF(D11="J",Notes!$B$2,Notes!$B$2*Notes!$B$3/(D11+Notes!$B$3))) | L11: =IF(E11="","",IF(E11="J",Notes!$B$2,Notes!$B$2*Notes!$B$3/(E11+Notes!$B$3))) | M11: =IF(F11="","",IF(F11="J",Notes!$B$2,Notes!$B$2*Notes!$B$3/(F11+Notes!$B$3))) | N11: =IF(G11="","",IF(G11="J",Notes!$B$2,Notes!$B$2*Notes!$B$3/(G11+Notes!$B$3))) | O11: =IF(H11="","",IF(H11="J",Notes!$B$2,Notes!$B$2*Notes!$B$3/(H11+Notes!$B$3)))
A12: 10 | B12: VR8 RESL | C12: J | D12: J | E12: 3.6 | F12: 15 | H12: J | J12: =IF(C12="","",IF(C12="J",Notes!$B$2,Notes!$B$2*Notes!$B$3/(C12+Notes!$B$3))) | K12: =IF(D12="","",IF(D12="J",Notes!$B$2,Notes!$B$2*Notes!$B$3/(D12+Notes!$B$3))) | L12: =IF(E12="","",IF(E12="J",Notes!$B$2,Notes!$B$2*Notes!$B$3/(E12+Notes!$B$3))) | M12: =IF(F12="","",IF(F12="J",Notes!$B$2,Notes!$B$2*Notes!$B$3/(F12+Notes!$B$3))) | N12: =IF(G12="","",IF(G12="J",Notes!$B$2,Notes!$B$2*Notes!$B$3/(G12+Notes!$B$3))) | O12: =IF(H12="","",IF(H12="J",Notes!$B$2,Notes!$B$2*Notes!$B$3/(H12+Notes!$B$3)))
A13: 11 | B13: VR9 IL | D13: 4.7 | E13: 9.1 | F13: 22 | G13: 130 | J13: =IF(C13="","",IF(C13="J",Notes!$B$2,Notes!$B$2*Notes!$B$3/(C13+Notes!$B$3))) | K13: =IF(D13="","",IF(D13="J",Notes!$B$2,Notes!$B$2*Notes!$B$3/(D13+Notes!$B$3))) | L13: =IF(E13="","",IF(E13="J",Notes!$B$2,Notes!$B$2*Notes!$B$3/(E13+Notes!$B$3))) | M13: =IF(F13="","",IF(F13="J",Notes!$B$2,Notes!$B$2*Notes!$B$3/(F13+Notes!$B$3))) | N13: =IF(G13="","",IF(G13="J",Notes!$B$2,Notes!$B$2*Notes!$B$3/(G13+Notes!$B$3))) | O13: =IF(H13="","",IF(H13="J",Notes!$B$2,Notes!$B$2*Notes!$B$3/(H13+Notes!$B$3)))
A14: 12 | B14: VR10 AL | D14: 30 | E14: 20 | F14: 1.6 | G14: 3.3 | H14: J | J14: =IF(C14="","",IF(C14="J",Notes!$B$2,Notes!$B$2*Notes!$B$3/(C14+Notes!$B$3))) | K14: =IF(D14="","",IF(D14="J",Notes!$B$2,Notes!$B$2*Notes!$B$3/(D14+Notes!$B$3))) | L14: =IF(E14="","",IF(E14="J",Notes!$B$2,Notes!$B$2*Notes!$B$3/(E14+Notes!$B$3))) | M14: =IF(F14="","",IF(F14="J",Notes!$B$2,Notes!$B$2*Notes!$B$3/(F14+Notes!$B$3))) | N14: =IF(G14="","",IF(G14="J",Notes!$B$2,Notes!$B$2*Notes!$B$3/(G14+Notes!$B$3))) | O14: =IF(H14="","",IF(H14="J",Notes!$B$2,Notes!$B$2*Notes!$B$3/(H14+Notes!$B$3)))
A15: 13 | B15: VR11 A | C15: J | D15: 8.2 | E15: 120 | F15: 15 | G15: J | H15: J | J15: =IF(C15="","",IF(C15="J",Notes!$B$2,Notes!$B$2*Notes!$B$3/(C15+Notes!$B$3))) | K15: =IF(D15="","",IF(D15="J",Notes!$B$2,Notes!$B$2*Notes!$B$3/(D15+Notes!$B$3))) | L15: =IF(E15="","",IF(E15="J",Notes!$B$2,Notes!$B$2*Notes!$B$3/(E15+Notes!$B$3))) | M15: =IF(F15="","",IF(F15="J",Notes!$B$2,Notes!$B$2*Notes!$B$3/(F15+Notes!$B$3))) | N15: =IF(G15="","",IF(G15="J",Notes!$B$2,Notes!$B$2*Notes!$B$3/(G15+Notes!$B$3))) | O15: =IF(H15="","",IF(H15="J",Notes!$B$2,Notes!$B$2*Notes!$B$3/(H15+Notes!$B$3)))
A16: 14 | B16: VR12 D | C16: J | D16: 7.5 | E16: 13 | F16: 12 | G16: 8.2 | H16: 22 | J16: =IF(C16="","",IF(C16="J",Notes!$B$2,Notes!$B$2*Notes!$B$3/(C16+Notes!$B$3))) | K16: =IF(D16="","",IF(D16="J",Notes!$B$2,Notes!$B$2*Notes!$B$3/(D16+Notes!$B$3))) | L16: =IF(E16="","",IF(E16="J",Notes!$B$2,Notes!$B$2*Notes!$B$3/(E16+Notes!$B$3))) | M16: =IF(F16="","",IF(F16="J",Notes!$B$2,Notes!$B$2*Notes!$B$3/(F16+Notes!$B$3))) | N16: =IF(G16="","",IF(G16="J",Notes!$B$2,Notes!$B$2*Notes!$B$3/(G16+Notes!$B$3))) | O16: =IF(H16="","",IF(H16="J",Notes!$B$2,Notes!$B$2*Notes!$B$3/(H16+Notes!$B$3)))
A17: 15 | B17: VR13 R | C17: J | D17: 3.3 | E17: J | F17: 3.9 | G17: 1.6 | H17: J | J17: =IF(C17="","",IF(C17="J",Notes!$B$2,Notes!$B$2*Notes!$B$3/(C17+Notes!$B$3))) | K17: =IF(D17="","",IF(D17="J",Notes!$B$2,Notes!$B$2*Notes!$B$3/(D17+Notes!$B$3))) | L17: =IF(E17="","",IF(E17="J",Notes!$B$2,Notes!$B$2*Notes!$B$3/(E17+Notes!$B$3))) | M17: =IF(F17="","",IF(F17="J",Notes!$B$2,Notes!$B$2*Notes!$B$3/(F17+Notes!$B$3))) | N17: =IF(G17="","",IF(G17="J",Notes!$B$2,Notes!$B$2*Notes!$B$3/(G17+Notes!$B$3))) | O17: =IF(H17="","",IF(H17="J",Notes!$B$2,Notes!$B$2*Notes!$B$3/(H17+Notes!$B$3)))
A18: 16 | B18: VR14 VCA level | C18: J | D18: J | E18: J | F18: J | G18: J | H18: J | J18: =IF(C18="","",IF(C18="J",Notes!$B$2,Notes!$B$2*Notes!$B$3/(C18+Notes!$B$3))) | K18: =IF(D18="","",IF(D18="J",Notes!$B$2,Notes!$B$2*Notes!$B$3/(D18+Notes!$B$3))) | L18: =IF(E18="","",IF(E18="J",Notes!$B$2,Notes!$B$2*Notes!$B$3/(E18+Notes!$B$3))) | M18: =IF(F18="","",IF(F18="J",Notes!$B$2,Notes!$B$2*Notes!$B$3/(F18+Notes!$B$3))) | N18: =IF(G18="","",IF(G18="J",Notes!$B$2,Notes!$B$2*Notes!$B$3/(G18+Notes!$B$3))) | O18: =IF(H18="","",IF(H18="J",Notes!$B$2,Notes!$B$2*Notes!$B$3/(H18+Notes!$B$3)))
A19: 17 | B19: VR15 wave symbol | J19: =IF(C19="","",IF(C19="J",Notes!$B$2,Notes!$B$2*Notes!$B$3/(C19+Notes!$B$3))) | K19: =IF(D19="","",IF(D19="J",Notes!$B$2,Notes!$B$2*Notes!$B$3/(D19+Notes!$B$3))) | L19: =IF(E19="","",IF(E19="J",Notes!$B$2,Notes!$B$2*Notes!$B$3/(E19+Notes!$B$3))) | M19: =IF(F19="","",IF(F19="J",Notes!$B$2,Notes!$B$2*Notes!$B$3/(F19+Notes!$B$3))) | N19: =IF(G19="","",IF(G19="J",Notes!$B$2,Notes!$B$2*Notes!$B$3/(G19+Notes!$B$3))) | O19: =IF(H19="","",IF(H19="J",Notes!$B$2,Notes!$B$2*Notes!$B$3/(H19+Notes!$B$3)))
A20: 18 | B20: VR16 A | C20: 2.2 | D20: 13 | E20: 9.1 | F20: 8.2 | G20: 4.3 | H20: J | J20: =IF(C20="","",IF(C20="J",Notes!$B$2,Notes!$B$2*Notes!$B$3/(C20+Notes!$B$3))) | K20: =IF(D20="","",IF(D20="J",Notes!$B$2,Notes!$B$2*Notes!$B$3/(D20+Notes!$B$3))) | L20: =IF(E20="","",IF(E20="J",Notes!$B$2,Notes!$B$2*Notes!$B$3/(E20+Notes!$B$3))) | M20: =IF(F20="","",IF(F20="J",Notes!$B$2,Notes!$B$2*Notes!$B$3/(F20+Notes!$B$3))) | N20: =IF(G20="","",IF(G20="J",Notes!$B$2,Notes!$B$2*Notes!$B$3/(G20+Notes!$B$3))) | O20: =IF(H20="","",IF(H20="J",Notes!$B$2,Notes!$B$2*Notes!$B$3/(H20+Notes!$B$3)))
A21: 19 | B21: VR17 D | C21: 47 | D21: J | E21: 36 | F21: 13 | G21: 33 | H21: 11 | J21: =IF(C21="","",IF(C21="J",Notes!$B$2,Notes!$B$2*Notes!$B$3/(C21+Notes!$B$3))) | K21: =IF(D21="","",IF(D21="J",Notes!$B$2,Notes!$B$2*Notes!$B$3/(D21+Notes!$B$3))) | L21: =IF(E21="","",IF(E21="J",Notes!$B$2,Notes!$B$2*Notes!$B$3/(E21+Notes!$B$3))) | M21: =IF(F21="","",IF(F21="J",Notes!$B$2,Notes!$B$2*Notes!$B$3/(F21+Notes!$B$3))) | N21: =IF(G21="","",IF(G21="J",Notes!$B$2,Notes!$B$2*Notes!$B$3/(G21+Notes!$B$3))) | O21: =IF(H21="","",IF(H21="J",Notes!$B$2,Notes!$B$2*Notes!$B$3/(H21+Notes!$B$3)))
A22: 20 | B22: VR18 S | C22: 1.2 | D22: 1.2 | E22: 1.2 | F22: 11 | H22: 43 | J22: =IF(C22="","",IF(C22="J",Notes!$B$2,Notes!$B$2*Notes!$B$3/(C22+Notes!$B$3))) | K22: =IF(D22="","",IF(D22="J",Notes!$B$2,Notes!$B$2*Notes!$B$3/(D22+Notes!$B$3))) | L22: =IF(E22="","",IF(E22="J",Notes!$B$2,Notes!$B$2*Notes!$B$3/(E22+Notes!$B$3))) | M22: =IF(F22="","",IF(F22="J",Notes!$B$2,Notes!$B$2*Notes!$B$3/(F22+Notes!$B$3))) | N22: =IF(G22="","",IF(G22="J",Notes!$B$2,Notes!$B$2*Notes!$B$3/(G22+Notes!$B$3))) | O22: =IF(H22="","",IF(H22="J",Notes!$B$2,Notes!$B$2*Notes!$B$3/(H22+Notes!$B$3)))
A23: 21 | B23: VR19 R | C23: 4.7 | D23: 2.7 | E23: J | F23: 5.1 | G23: J | H23: 2 | J23: =IF(C23="","",IF(C23="J",Notes!$B$2,Notes!$B$2*Notes!$B$3/(C23+Notes!$B$3))) | K23: =IF(D23="","",IF(D23="J",Notes!$B$2,Notes!$B$2*Notes!$B$3/(D23+Notes!$B$3))) | L23: =IF(E23="","",IF(E23="J",Notes!$B$2,Notes!$B$2*Notes!$B$3/(E23+Notes!$B$3))) | M23: =IF(F23="","",IF(F23="J",Notes!$B$2,Notes!$B$2*Notes!$B$3/(F23+Notes!$B$3))) | N23: =IF(G23="","",IF(G23="J",Notes!$B$2,Notes!$B$2*Notes!$B$3/(G23+Notes!$B$3))) | O23: =IF(H23="","",IF(H23="J",Notes!$B$2,Notes!$B$2*Notes!$B$3/(H23+Notes!$B$3)))
A24: 22 | B24: VR20 level | C24: J | D24: 1.8 | E24: J | F24: 1.8 | G24: J | H24: 12 | J24: =IF(C24="","",IF(C24="J",Notes!$B$2,Notes!$B$2*Notes!$B$3/(C24+Notes!$B$3))) | K24: =IF(D24="","",IF(D24="J",Notes!$B$2,Notes!$B$2*Notes!$B$3/(D24+Notes!$B$3))) | L24: =IF(E24="","",IF(E24="J",Notes!$B$2,Notes!$B$2*Notes!$B$3/(E24+Notes!$B$3))) | M24: =IF(F24="","",IF(F24="J",Notes!$B$2,Notes!$B$2*Notes!$B$3/(F24+Notes!$B$3))) | N24: =IF(G24="","",IF(G24="J",Notes!$B$2,Notes!$B$2*Notes!$B$3/(G24+Notes!$B$3))) | O24: =IF(H24="","",IF(H24="J",Notes!$B$2,Notes!$B$2*Notes!$B$3/(H24+Notes!$B$3)))
A25: 23 | B25: VR21 touch: init brilliance | C25: 22 | D25: 22 | E25: 22 | F25: 22 | G25: 22 | H25: 16 | J25: =IF(C25="","",IF(C25="J",Notes!$B$2,Notes!$B$2*Notes!$B$3/(C25+Notes!$B$3))) | K25: =IF(D25="","",IF(D25="J",Notes!$B$2,Notes!$B$2*Notes!$B$3/(D25+Notes!$B$3))) | L25: =IF(E25="","",IF(E25="J",Notes!$B$2,Notes!$B$2*Notes!$B$3/(E25+Notes!$B$3))) | M25: =IF(F25="","",IF(F25="J",Notes!$B$2,Notes!$B$2*Notes!$B$3/(F25+Notes!$B$3))) | N25: =IF(G25="","",IF(G25="J",Notes!$B$2,Notes!$B$2*Notes!$B$3/(G25+Notes!$B$3))) | O25: =IF(H25="","",IF(H25="J",Notes!$B$2,Notes!$B$2*Notes!$B$3/(H25+Notes!$B$3)))
A26: 24 | B26: VR22 touch: init level | C26: J | D26: J | E26: J | F26: J | G26: J | H26: J | J26: =IF(C26="","",IF(C26="J",Notes!$B$2,Notes!$B$2*Notes!$B$3/(C26+Notes!$B$3))) | K26: =IF(D26="","",IF(D26="J",Notes!$B$2,Notes!$B$2*Notes!$B$3/(D26+Notes!$B$3))) | L26: =IF(E26="","",IF(E26="J",Notes!$B$2,Notes!$B$2*Notes!$B$3/(E26+Notes!$B$3))) | M26: =IF(F26="","",IF(F26="J",Notes!$B$2,Notes!$B$2*Notes!$B$3/(F26+Notes!$B$3))) | N26: =IF(G26="","",IF(G26="J",Notes!$B$2,Notes!$B$2*Notes!$B$3/(G26+Notes!$B$3))) | O26: =IF(H26="","",IF(H26="J",Notes!$B$2,Notes!$B$2*Notes!$B$3/(H26+Notes!$B$3)))
A27: 25 | B27: VR23 touch: after brilliance | C27: J | D27: 13 | E27: 10 | F27: 10 | J27: =IF(C27="","",IF(C27="J",Notes!$B$2,Notes!$B$2*Notes!$B$3/(C27+Notes!$B$3))) | K27: =IF(D27="","",IF(D27="J",Notes!$B$2,Notes!$B$2*Notes!$B$3/(D27+Notes!$B$3))) | L27: =IF(E27="","",IF(E27="J",Notes!$B$2,Notes!$B$2*Notes!$B$3/(E27+Notes!$B$3))) | M27: =IF(F27="","",IF(F27="J",Notes!$B$2,Notes!$B$2*Notes!$B$3/(F27+Notes!$B$3))) | N27: =IF(G27="","",IF(G27="J",Notes!$B$2,Notes!$B$2*Notes!$B$3/(G27+Notes!$B$3))) | O27: =IF(H27="","",IF(H27="J",Notes!$B$2,Notes!$B$2*Notes!$B$3/(H27+Notes!$B$3)))
A28: 26 | B28: VR24 touch: after level | C28: J | D28: J | E28: J | F28: J | G28: J | H28: J | J28: =IF(C28="","",IF(C28="J",Notes!$B$2,Notes!$B$2*Notes!$B$3/(C28+Notes!$B$3))) | K28: =IF(D28="","",IF(D28="J",Notes!$B$2,Notes!$B$2*Notes!$B$3/(D28+Notes!$B$3))) | L28: =IF(E28="","",IF(E28="J",Notes!$B$2,Notes!$B$2*Notes!$B$3/(E28+Notes!$B$3))) | M28: =IF(F28="","",IF(F28="J",Notes!$B$2,Notes!$B$2*Notes!$B$3/(F28+Notes!$B$3))) | N28: =IF(G28="","",IF(G28="J",Notes!$B$2,Notes!$B$2*Notes!$B$3/(G28+Notes!$B$3))) | O28: =IF(H28="","",IF(H28="J",Notes!$B$2,Notes!$B$2*Notes!$B$3/(H28+Notes!$B$3)))

Sheet T54 p37
A1: T54 as drawn (p.37)
A2: Row | B2: Slider / function | C2: Bus A (R, kΩ) | D2: Bus B (R, kΩ) | E2: Bus C (R, kΩ) | F2: Bus D (R, kΩ) | G2: Bus E (R, kΩ) | I2: A level (V) | J2: B level (V) | K2: C level (V) | L2: D level (V) | M2: E level (V)
A3: 1 | B3: VR1 Speed | I3: =IF(C3="","",IF(C3="J",Notes!$B$2,Notes!$B$2*Notes!$B$3/(C3+Notes!$B$3))) | J3: =IF(D3="","",IF(D3="J",Notes!$B$2,Notes!$B$2*Notes!$B$3/(D3+Notes!$B$3))) | K3: =IF(E3="","",IF(E3="J",Notes!$B$2,Notes!$B$2*Notes!$B$3/(E3+Notes!$B$3))) | L3: =IF(F3="","",IF(F3="J",Notes!$B$2,Notes!$B$2*Notes!$B$3/(F3+Notes!$B$3))) | M3: =IF(G3="","",IF(G3="J",Notes!$B$2,Notes!$B$2*Notes!$B$3/(G3+Notes!$B$3)))
A4: 2 | B4: VR2 PWM | I4: =IF(C4="","",IF(C4="J",Notes!$B$2,Notes!$B$2*Notes!$B$3/(C4+Notes!$B$3))) | J4: =IF(D4="","",IF(D4="J",Notes!$B$2,Notes!$B$2*Notes!$B$3/(D4+Notes!$B$3))) | K4: =IF(E4="","",IF(E4="J",Notes!$B$2,Notes!$B$2*Notes!$B$3/(E4+Notes!$B$3))) | L4: =IF(F4="","",IF(F4="J",Notes!$B$2,Notes!$B$2*Notes!$B$3/(F4+Notes!$B$3))) | M4: =IF(G4="","",IF(G4="J",Notes!$B$2,Notes!$B$2*Notes!$B$3/(G4+Notes!$B$3)))
A5: 3 | B5: VR3 PW | C5: 7.5 | I5: =IF(C5="","",IF(C5="J",Notes!$B$2,Notes!$B$2*Notes!$B$3/(C5+Notes!$B$3))) | J5: =IF(D5="","",IF(D5="J",Notes!$B$2,Notes!$B$2*Notes!$B$3/(D5+Notes!$B$3))) | K5: =IF(E5="","",IF(E5="J",Notes!$B$2,Notes!$B$2*Notes!$B$3/(E5+Notes!$B$3))) | L5: =IF(F5="","",IF(F5="J",Notes!$B$2,Notes!$B$2*Notes!$B$3/(F5+Notes!$B$3))) | M5: =IF(G5="","",IF(G5="J",Notes!$B$2,Notes!$B$2*Notes!$B$3/(G5+Notes!$B$3)))
A6: 4 | B6: SW1 square | C6: J | D6: J | I6: =IF(C6="","",IF(C6="J",Notes!$B$2,Notes!$B$2*Notes!$B$3/(C6+Notes!$B$3))) | J6: =IF(D6="","",IF(D6="J",Notes!$B$2,Notes!$B$2*Notes!$B$3/(D6+Notes!$B$3))) | K6: =IF(E6="","",IF(E6="J",Notes!$B$2,Notes!$B$2*Notes!$B$3/(E6+Notes!$B$3))) | L6: =IF(F6="","",IF(F6="J",Notes!$B$2,Notes!$B$2*Notes!$B$3/(F6+Notes!$B$3))) | M6: =IF(G6="","",IF(G6="J",Notes!$B$2,Notes!$B$2*Notes!$B$3/(G6+Notes!$B$3)))
A7: 5 | B7: SW2 saw/ramp | E7: J | F7: J | G7: J | I7: =IF(C7="","",IF(C7="J",Notes!$B$2,Notes!$B$2*Notes!$B$3/(C7+Notes!$B$3))) | J7: =IF(D7="","",IF(D7="J",Notes!$B$2,Notes!$B$2*Notes!$B$3/(D7+Notes!$B$3))) | K7: =IF(E7="","",IF(E7="J",Notes!$B$2,Notes!$B$2*Notes!$B$3/(E7+Notes!$B$3))) | L7: =IF(F7="","",IF(F7="J",Notes!$B$2,Notes!$B$2*Notes!$B$3/(F7+Notes!$B$3))) | M7: =IF(G7="","",IF(G7="J",Notes!$B$2,Notes!$B$2*Notes!$B$3/(G7+Notes!$B$3)))
A8: 6 | B8: VR4 Noise | I8: =IF(C8="","",IF(C8="J",Notes!$B$2,Notes!$B$2*Notes!$B$3/(C8+Notes!$B$3))) | J8: =IF(D8="","",IF(D8="J",Notes!$B$2,Notes!$B$2*Notes!$B$3/(D8+Notes!$B$3))) | K8: =IF(E8="","",IF(E8="J",Notes!$B$2,Notes!$B$2*Notes!$B$3/(E8+Notes!$B$3))) | L8: =IF(F8="","",IF(F8="J",Notes!$B$2,Notes!$B$2*Notes!$B$3/(F8+Notes!$B$3))) | M8: =IF(G8="","",IF(G8="J",Notes!$B$2,Notes!$B$2*Notes!$B$3/(G8+Notes!$B$3)))
A9: 7 | B9: HPF (BA fo1/fo3) | C9: 2.7 | E9: 22 | F9: 7.5 | G9: 6.8 | I9: =IF(C9="","",IF(C9="J",Notes!$B$2,Notes!$B$2*Notes!$B$3/(C9+Notes!$B$3))) | J9: =IF(D9="","",IF(D9="J",Notes!$B$2,Notes!$B$2*Notes!$B$3/(D9+Notes!$B$3))) | K9: =IF(E9="","",IF(E9="J",Notes!$B$2,Notes!$B$2*Notes!$B$3/(E9+Notes!$B$3))) | L9: =IF(F9="","",IF(F9="J",Notes!$B$2,Notes!$B$2*Notes!$B$3/(F9+Notes!$B$3))) | M9: =IF(G9="","",IF(G9="J",Notes!$B$2,Notes!$B$2*Notes!$B$3/(G9+Notes!$B$3)))
A10: 8 | B10: VR6 RESH | C10: J | D10: J | F10: 5.6 | I10: =IF(C10="","",IF(C10="J",Notes!$B$2,Notes!$B$2*Notes!$B$3/(C10+Notes!$B$3))) | J10: =IF(D10="","",IF(D10="J",Notes!$B$2,Notes!$B$2*Notes!$B$3/(D10+Notes!$B$3))) | K10: =IF(E10="","",IF(E10="J",Notes!$B$2,Notes!$B$2*Notes!$B$3/(E10+Notes!$B$3))) | L10: =IF(F10="","",IF(F10="J",Notes!$B$2,Notes!$B$2*Notes!$B$3/(F10+Notes!$B$3))) | M10: =IF(G10="","",IF(G10="J",Notes!$B$2,Notes!$B$2*Notes!$B$3/(G10+Notes!$B$3)))
A11: 9 | B11: LPF (BA fo2/fo4) | C11: 1.9 | D11: 6.2 | E11: 18 | F11: 4.3 | G11: 6.2 | I11: =IF(C11="","",IF(C11="J",Notes!$B$2,Notes!$B$2*Notes!$B$3/(C11+Notes!$B$3))) | J11: =IF(D11="","",IF(D11="J",Notes!$B$2,Notes!$B$2*Notes!$B$3/(D11+Notes!$B$3))) | K11: =IF(E11="","",IF(E11="J",Notes!$B$2,Notes!$B$2*Notes!$B$3/(E11+Notes!$B$3))) | L11: =IF(F11="","",IF(F11="J",Notes!$B$2,Notes!$B$2*Notes!$B$3/(F11+Notes!$B$3))) | M11: =IF(G11="","",IF(G11="J",Notes!$B$2,Notes!$B$2*Notes!$B$3/(G11+Notes!$B$3)))
A12: 10 | B12: VR8 RESL | C12: J | F12: 18 | G12: 5.1 | I12: =IF(C12="","",IF(C12="J",Notes!$B$2,Notes!$B$2*Notes!$B$3/(C12+Notes!$B$3))) | J12: =IF(D12="","",IF(D12="J",Notes!$B$2,Notes!$B$2*Notes!$B$3/(D12+Notes!$B$3))) | K12: =IF(E12="","",IF(E12="J",Notes!$B$2,Notes!$B$2*Notes!$B$3/(E12+Notes!$B$3))) | L12: =IF(F12="","",IF(F12="J",Notes!$B$2,Notes!$B$2*Notes!$B$3/(F12+Notes!$B$3))) | M12: =IF(G12="","",IF(G12="J",Notes!$B$2,Notes!$B$2*Notes!$B$3/(G12+Notes!$B$3)))
A13: 11 | B13: VR9 IL | F13: 3.9 | I13: =IF(C13="","",IF(C13="J",Notes!$B$2,Notes!$B$2*Notes!$B$3/(C13+Notes!$B$3))) | J13: =IF(D13="","",IF(D13="J",Notes!$B$2,Notes!$B$2*Notes!$B$3/(D13+Notes!$B$3))) | K13: =IF(E13="","",IF(E13="J",Notes!$B$2,Notes!$B$2*Notes!$B$3/(E13+Notes!$B$3))) | L13: =IF(F13="","",IF(F13="J",Notes!$B$2,Notes!$B$2*Notes!$B$3/(F13+Notes!$B$3))) | M13: =IF(G13="","",IF(G13="J",Notes!$B$2,Notes!$B$2*Notes!$B$3/(G13+Notes!$B$3)))
A14: 12 | B14: VR10 AL | E14: 2.4 | F14: 4.7 | G14: J | I14: =IF(C14="","",IF(C14="J",Notes!$B$2,Notes!$B$2*Notes!$B$3/(C14+Notes!$B$3))) | J14: =IF(D14="","",IF(D14="J",Notes!$B$2,Notes!$B$2*Notes!$B$3/(D14+Notes!$B$3))) | K14: =IF(E14="","",IF(E14="J",Notes!$B$2,Notes!$B$2*Notes!$B$3/(E14+Notes!$B$3))) | L14: =IF(F14="","",IF(F14="J",Notes!$B$2,Notes!$B$2*Notes!$B$3/(F14+Notes!$B$3))) | M14: =IF(G14="","",IF(G14="J",Notes!$B$2,Notes!$B$2*Notes!$B$3/(G14+Notes!$B$3)))
A15: 13 | B15: VR11 A | C15: J | D15: J | E15: J | F15: 16 | G15: 11 | I15: =IF(C15="","",IF(C15="J",Notes!$B$2,Notes!$B$2*Notes!$B$3/(C15+Notes!$B$3))) | J15: =IF(D15="","",IF(D15="J",Notes!$B$2,Notes!$B$2*Notes!$B$3/(D15+Notes!$B$3))) | K15: =IF(E15="","",IF(E15="J",Notes!$B$2,Notes!$B$2*Notes!$B$3/(E15+Notes!$B$3))) | L15: =IF(F15="","",IF(F15="J",Notes!$B$2,Notes!$B$2*Notes!$B$3/(F15+Notes!$B$3))) | M15: =IF(G15="","",IF(G15="J",Notes!$B$2,Notes!$B$2*Notes!$B$3/(G15+Notes!$B$3)))
A16: 14 | B16: VR12 D | C16: J | D16: J | E16: 36 | F16: 8.2 | G16: 15 | I16: =IF(C16="","",IF(C16="J",Notes!$B$2,Notes!$B$2*Notes!$B$3/(C16+Notes!$B$3))) | J16: =IF(D16="","",IF(D16="J",Notes!$B$2,Notes!$B$2*Notes!$B$3/(D16+Notes!$B$3))) | K16: =IF(E16="","",IF(E16="J",Notes!$B$2,Notes!$B$2*Notes!$B$3/(E16+Notes!$B$3))) | L16: =IF(F16="","",IF(F16="J",Notes!$B$2,Notes!$B$2*Notes!$B$3/(F16+Notes!$B$3))) | M16: =IF(G16="","",IF(G16="J",Notes!$B$2,Notes!$B$2*Notes!$B$3/(G16+Notes!$B$3)))
A17: 15 | B17: VR13 R | C17: J | D17: J | E17: 3.9 | F17: J | G17: J | I17: =IF(C17="","",IF(C17="J",Notes!$B$2,Notes!$B$2*Notes!$B$3/(C17+Notes!$B$3))) | J17: =IF(D17="","",IF(D17="J",Notes!$B$2,Notes!$B$2*Notes!$B$3/(D17+Notes!$B$3))) | K17: =IF(E17="","",IF(E17="J",Notes!$B$2,Notes!$B$2*Notes!$B$3/(E17+Notes!$B$3))) | L17: =IF(F17="","",IF(F17="J",Notes!$B$2,Notes!$B$2*Notes!$B$3/(F17+Notes!$B$3))) | M17: =IF(G17="","",IF(G17="J",Notes!$B$2,Notes!$B$2*Notes!$B$3/(G17+Notes!$B$3)))
A18: 16 | B18: VR14 VCA level | C18: J | D18: J | E18: J | F18: J | G18: J | I18: =IF(C18="","",IF(C18="J",Notes!$B$2,Notes!$B$2*Notes!$B$3/(C18+Notes!$B$3))) | J18: =IF(D18="","",IF(D18="J",Notes!$B$2,Notes!$B$2*Notes!$B$3/(D18+Notes!$B$3))) | K18: =IF(E18="","",IF(E18="J",Notes!$B$2,Notes!$B$2*Notes!$B$3/(E18+Notes!$B$3))) | L18: =IF(F18="","",IF(F18="J",Notes!$B$2,Notes!$B$2*Notes!$B$3/(F18+Notes!$B$3))) | M18: =IF(G18="","",IF(G18="J",Notes!$B$2,Notes!$B$2*Notes!$B$3/(G18+Notes!$B$3)))
A19: 17 | B19: VR15 wave symbol | E19: 6.8 | G19: J | I19: =IF(C19="","",IF(C19="J",Notes!$B$2,Notes!$B$2*Notes!$B$3/(C19+Notes!$B$3))) | J19: =IF(D19="","",IF(D19="J",Notes!$B$2,Notes!$B$2*Notes!$B$3/(D19+Notes!$B$3))) | K19: =IF(E19="","",IF(E19="J",Notes!$B$2,Notes!$B$2*Notes!$B$3/(E19+Notes!$B$3))) | L19: =IF(F19="","",IF(F19="J",Notes!$B$2,Notes!$B$2*Notes!$B$3/(F19+Notes!$B$3))) | M19: =IF(G19="","",IF(G19="J",Notes!$B$2,Notes!$B$2*Notes!$B$3/(G19+Notes!$B$3)))
A20: 18 | B20: VR16 A | C20: J | D20: J | E20: J | F20: 3.6 | G20: J | I20: =IF(C20="","",IF(C20="J",Notes!$B$2,Notes!$B$2*Notes!$B$3/(C20+Notes!$B$3))) | J20: =IF(D20="","",IF(D20="J",Notes!$B$2,Notes!$B$2*Notes!$B$3/(D20+Notes!$B$3))) | K20: =IF(E20="","",IF(E20="J",Notes!$B$2,Notes!$B$2*Notes!$B$3/(E20+Notes!$B$3))) | L20: =IF(F20="","",IF(F20="J",Notes!$B$2,Notes!$B$2*Notes!$B$3/(F20+Notes!$B$3))) | M20: =IF(G20="","",IF(G20="J",Notes!$B$2,Notes!$B$2*Notes!$B$3/(G20+Notes!$B$3)))
A21: 19 | B21: VR17 D | C21: 16 | D21: 5.6 | E21: 82 | F21: 13 | G21: 11 | I21: =IF(C21="","",IF(C21="J",Notes!$B$2,Notes!$B$2*Notes!$B$3/(C21+Notes!$B$3))) | J21: =IF(D21="","",IF(D21="J",Notes!$B$2,Notes!$B$2*Notes!$B$3/(D21+Notes!$B$3))) | K21: =IF(E21="","",IF(E21="J",Notes!$B$2,Notes!$B$2*Notes!$B$3/(E21+Notes!$B$3))) | L21: =IF(F21="","",IF(F21="J",Notes!$B$2,Notes!$B$2*Notes!$B$3/(F21+Notes!$B$3))) | M21: =IF(G21="","",IF(G21="J",Notes!$B$2,Notes!$B$2*Notes!$B$3/(G21+Notes!$B$3)))
A22: 20 | B22: VR18 S | D22: 39 | E22: 330 | F22: 33 | G22: 12 | I22: =IF(C22="","",IF(C22="J",Notes!$B$2,Notes!$B$2*Notes!$B$3/(C22+Notes!$B$3))) | J22: =IF(D22="","",IF(D22="J",Notes!$B$2,Notes!$B$2*Notes!$B$3/(D22+Notes!$B$3))) | K22: =IF(E22="","",IF(E22="J",Notes!$B$2,Notes!$B$2*Notes!$B$3/(E22+Notes!$B$3))) | L22: =IF(F22="","",IF(F22="J",Notes!$B$2,Notes!$B$2*Notes!$B$3/(F22+Notes!$B$3))) | M22: =IF(G22="","",IF(G22="J",Notes!$B$2,Notes!$B$2*Notes!$B$3/(G22+Notes!$B$3)))
A23: 21 | B23: VR19 R | C23: J | D23: J | E23: 2.7 | F23: J | G23: J | I23: =IF(C23="","",IF(C23="J",Notes!$B$2,Notes!$B$2*Notes!$B$3/(C23+Notes!$B$3))) | J23: =IF(D23="","",IF(D23="J",Notes!$B$2,Notes!$B$2*Notes!$B$3/(D23+Notes!$B$3))) | K23: =IF(E23="","",IF(E23="J",Notes!$B$2,Notes!$B$2*Notes!$B$3/(E23+Notes!$B$3))) | L23: =IF(F23="","",IF(F23="J",Notes!$B$2,Notes!$B$2*Notes!$B$3/(F23+Notes!$B$3))) | M23: =IF(G23="","",IF(G23="J",Notes!$B$2,Notes!$B$2*Notes!$B$3/(G23+Notes!$B$3)))
A24: 22 | B24: VR20 level | C24: J | D24: J | E24: 12 | F24: 4.7 | G24: J | I24: =IF(C24="","",IF(C24="J",Notes!$B$2,Notes!$B$2*Notes!$B$3/(C24+Notes!$B$3))) | J24: =IF(D24="","",IF(D24="J",Notes!$B$2,Notes!$B$2*Notes!$B$3/(D24+Notes!$B$3))) | K24: =IF(E24="","",IF(E24="J",Notes!$B$2,Notes!$B$2*Notes!$B$3/(E24+Notes!$B$3))) | L24: =IF(F24="","",IF(F24="J",Notes!$B$2,Notes!$B$2*Notes!$B$3/(F24+Notes!$B$3))) | M24: =IF(G24="","",IF(G24="J",Notes!$B$2,Notes!$B$2*Notes!$B$3/(G24+Notes!$B$3)))
A25: 23 | B25: VR21 touch: init brilliance | E25: 22 | F25: 8.2 | G25: 12 | I25: =IF(C25="","",IF(C25="J",Notes!$B$2,Notes!$B$2*Notes!$B$3/(C25+Notes!$B$3))) | J25: =IF(D25="","",IF(D25="J",Notes!$B$2,Notes!$B$2*Notes!$B$3/(D25+Notes!$B$3))) | K25: =IF(E25="","",IF(E25="J",Notes!$B$2,Notes!$B$2*Notes!$B$3/(E25+Notes!$B$3))) | L25: =IF(F25="","",IF(F25="J",Notes!$B$2,Notes!$B$2*Notes!$B$3/(F25+Notes!$B$3))) | M25: =IF(G25="","",IF(G25="J",Notes!$B$2,Notes!$B$2*Notes!$B$3/(G25+Notes!$B$3)))
A26: 24 | B26: VR22 touch: init level | C26: J | D26: J | E26: J | F26: J | G26: J | I26: =IF(C26="","",IF(C26="J",Notes!$B$2,Notes!$B$2*Notes!$B$3/(C26+Notes!$B$3))) | J26: =IF(D26="","",IF(D26="J",Notes!$B$2,Notes!$B$2*Notes!$B$3/(D26+Notes!$B$3))) | K26: =IF(E26="","",IF(E26="J",Notes!$B$2,Notes!$B$2*Notes!$B$3/(E26+Notes!$B$3))) | L26: =IF(F26="","",IF(F26="J",Notes!$B$2,Notes!$B$2*Notes!$B$3/(F26+Notes!$B$3))) | M26: =IF(G26="","",IF(G26="J",Notes!$B$2,Notes!$B$2*Notes!$B$3/(G26+Notes!$B$3)))
A27: 25 | B27: VR23 touch: after brilliance | E27: 36 | G27: 5.6 | I27: =IF(C27="","",IF(C27="J",Notes!$B$2,Notes!$B$2*Notes!$B$3/(C27+Notes!$B$3))) | J27: =IF(D27="","",IF(D27="J",Notes!$B$2,Notes!$B$2*Notes!$B$3/(D27+Notes!$B$3))) | K27: =IF(E27="","",IF(E27="J",Notes!$B$2,Notes!$B$2*Notes!$B$3/(E27+Notes!$B$3))) | L27: =IF(F27="","",IF(F27="J",Notes!$B$2,Notes!$B$2*Notes!$B$3/(F27+Notes!$B$3))) | M27: =IF(G27="","",IF(G27="J",Notes!$B$2,Notes!$B$2*Notes!$B$3/(G27+Notes!$B$3)))
A28: 26 | B28: VR24 touch: after level | C28: J | D28: J | E28: J | F28: J | G28: J | I28: =IF(C28="","",IF(C28="J",Notes!$B$2,Notes!$B$2*Notes!$B$3/(C28+Notes!$B$3))) | J28: =IF(D28="","",IF(D28="J",Notes!$B$2,Notes!$B$2*Notes!$B$3/(D28+Notes!$B$3))) | K28: =IF(E28="","",IF(E28="J",Notes!$B$2,Notes!$B$2*Notes!$B$3/(E28+Notes!$B$3))) | L28: =IF(F28="","",IF(F28="J",Notes!$B$2,Notes!$B$2*Notes!$B$3/(F28+Notes!$B$3))) | M28: =IF(G28="","",IF(G28="J",Notes!$B$2,Notes!$B$2*Notes!$B$3/(G28+Notes!$B$3)))

Sheet Compare
A1: Row | B1: Bus | C1: T51 revised (ch I) | D1: T53 (ch II) | E1: Same? | F1: T52 revised (ch I) | G1: T54 (ch II) | H1: Same?
A2: 2 | B2: F | D2: 110 | E2: DIFF
A3: 3 | B3: A | F3: 7.5 | G3: 7.5 | H3: =
A4: 3 | B4: C | F4: 13 | H4: DIFF
A5: 3 | B5: E | C5: 7.5 | D5: 7.5 | E5: =
A6: 3 | B6: F | D6: J | E6: DIFF
A7: 4 | B7: A | F7: J | G7: J | H7: =
A8: 4 | B8: B | G8: J | H8: DIFF
A9: 4 | B9: C | F9: J | H9: DIFF
A10: 4 | B10: D | F10: J | H10: DIFF
A11: 4 | B11: E | C11: J | D11: J | E11: = | F11: J | H11: DIFF
A12: 4 | B12: F | C12: J | D12: J | E12: =
A13: 5 | B13: A | C13: J | D13: J | E13: =
A14: 5 | B14: B | C14: J | D14: J | E14: = | F14: J | H14: DIFF
A15: 5 | B15: C | C15: J | D15: J | E15: = | G15: J | H15: DIFF
A16: 5 | B16: D | C16: J | D16: J | E16: = | F16: J | G16: J | H16: =
A17: 5 | B17: E | G17: J | H17: DIFF
A18: 5 | B18: F | C18: J | D18: J | E18: =
A19: 7 | B19: A | C19: 6.2 | D19: 6.2 | E19: = | F19: 2.7 | G19: 2.7 | H19: =
A20: 7 | B20: B | D20: 27 | E20: DIFF
A21: 7 | B21: C | F21: 22 | G21: 22 | H21: =
A22: 7 | B22: D | C22: 27 | D22: 27 | E22: = | F22: 7.5 | G22: 7.5 | H22: =
A23: 7 | B23: E | F23: 6.8 | G23: 6.8 | H23: =
A24: 8 | B24: A | C24: J | D24: J | E24: = | F24: J | G24: J | H24: =
A25: 8 | B25: B | C25: J | D25: J | E25: = | F25: J | G25: J | H25: =
A26: 8 | B26: C | C26: J | D26: J | E26: = | F26: 6.8 | H26: DIFF
A27: 8 | B27: D | C27: 18 | D27: 15 | E27: DIFF | F27: 5.6 | G27: 5.6 | H27: =
A28: 8 | B28: E | C28: J | D28: J | E28: =
A29: 8 | B29: F | C29: J | D29: J | E29: =
A30: 9 | B30: A | C30: 0.75 | D30: 0.75 | E30: = | F30: 1.8 | G30: 1.9 | H30: DIFF
A31: 9 | B31: B | C31: 1.6 | D31: 1.6 | E31: = | F31: 6.2 | G31: 6.2 | H31: =
A32: 9 | B32: C | C32: 4.3 | D32: 4.3 | E32: = | F32: 18 | G32: 18 | H32: =
A33: 9 | B33: D | C33: 13 | D33: 13 | E33: = | F33: 4.3 | G33: 4.3 | H33: =
A34: 9 | B34: E | C34: 12 | D34: 12 | E34: = | F34: 6.2 | G34: 6.2 | H34: =
A35: 10 | B35: A | C35: J | D35: J | E35: = | F35: J | G35: J | H35: =
A36: 10 | B36: B | C36: J | D36: J | E36: =
A37: 10 | B37: C | C37: 3.6 | D37: 3.6 | E37: = | F37: 27 | H37: DIFF
A38: 10 | B38: D | C38: 15 | D38: 15 | E38: = | F38: 18 | G38: 18 | H38: =
A39: 10 | B39: E | F39: 51 | G39: 5.1 | H39: DIFF
A40: 10 | B40: F | C40: J | D40: J | E40: =
...
